<?xml version="1.0" ?>
<sdf version="1.7">
    <world name="car_world">
        <physics name="1ms" type="ignored">
            <max_step_size>0.001</max_step_size>
            <real_time_factor>1.0</real_time_factor>
        </physics>

        <plugin
            filename="libignition-gazebo-physics-system.so"
            name="ignition::gazebo::systems::Physics">
        </plugin>
        <plugin
            filename="libignition-gazebo-user-commands-system.so"
            name="ignition::gazebo::systems::UserCommands">
        </plugin>
        <plugin
            filename="libignition-gazebo-scene-broadcaster-system.so"
            name="ignition::gazebo::systems::SceneBroadcaster">
        </plugin>

        <light type="directional" name="sun">
            <cast_shadows>true</cast_shadows>
            <pose>0 0 10 0 0 0</pose>
            <diffuse>0.8 0.8 0.8 1</diffuse>
            <specular>0.2 0.2 0.2 1</specular>
            <attenuation>
                <range>1000</range>
                <constant>0.9</constant>
                <linear>0.01</linear>
                <quadratic>0.001</quadratic>
            </attenuation>
            <direction>-0.5 0.1 -0.9</direction>
        </light>

        <model name="ground_plane">
            <static>true</static>
            <link name="link">
                <collision name="collision">
                <geometry>
                    <plane>
                    <normal>0 0 1</normal>
                    </plane>
                </geometry>
                </collision>
                <visual name="visual">
                <geometry>
                    <plane>
                    <normal>0 0 1</normal>
                    <size>100 100</size>
                    </plane>
                </geometry>
                <material>
                    <ambient>0.8 0.8 0.8 1</ambient>
                    <diffuse>0.8 0.8 0.8 1</diffuse>
                    <specular>0.8 0.8 0.8 1</specular>
                </material>
                </visual>
            </link>
        </model>

        <model name='ackermann_robot' canonical_link='chassis'>

            <link name='chassis'>
                <pose relative_to='__model__'>0 0 0.1 0 0 0</pose>
                <inertial> <!--inertial properties of the link mass, inertia matix-->
                    <mass>1.14395</mass>
                    <inertia>
                        <ixx>0.095329</ixx>
                        <ixy>0</ixy>
                        <ixz>0</ixz>
                        <iyy>0.381317</iyy>
                        <iyz>0</iyz>
                        <izz>0.476646</izz>
                    </inertia>
                </inertial>
                <visual name='visual'>
                    <geometry>
                        <box>
                            <size>0.5 0.3 0.1</size>
                        </box>
                    </geometry>
                    <!--Color of the link-->
                    <material>
                        <ambient>0.0 0.0 1.0 1</ambient>
                        <diffuse>0.0 0.0 1.0 1</diffuse>
                        <specular>0.0 0.0 1.0 1</specular>
                    </material>
                </visual>
                <collision name='collision'>
                    <geometry>
                        <box>
                            <size>0.5 0.3 0.1</size>
                        </box>
                    </geometry>
                </collision>
            </link>

            <!--Front left wheel-->
            <link name='front_left_wheel'>
                <pose relative_to="chassis">0.2 0.15 -0.05 -1.5707 0 0</pose> <!--angles are in radian-->
                <inertial>
                    <mass>1</mass>
                    <inertia>
                        <ixx>0.043333</ixx>
                        <ixy>0</ixy>
                        <ixz>0</ixz>
                        <iyy>0.043333</iyy>
                        <iyz>0</iyz>
                        <izz>0.08</izz>
                    </inertia>
                </inertial>
                <visual name='visual'>
                    <geometry>
                        <cylinder>
                            <radius>0.05</radius>
                            <length>0.04</length>
                        </cylinder>
                    </geometry>
                    <material>
                        <ambient>1.0 0.0 0.0 1</ambient>
                        <diffuse>1.0 0.0 0.0 1</diffuse>
                        <specular>1.0 0.0 0.0 1</specular>
                    </material>
                </visual>
                <collision name='collision'>
                    <geometry>
                        <cylinder>
                            <radius>0.05</radius>
                            <length>0.04</length>
                        </cylinder>
                    </geometry>
                </collision>
            </link>

            <!--Front right wheel-->
            <link name='front_right_wheel'>
                <pose relative_to="chassis">0.2 -0.15 -0.05 -1.5707 0 0</pose> <!--angles are in radian-->
                <inertial>
                    <mass>1</mass>
                    <inertia>
                        <ixx>0.043333</ixx>
                        <ixy>0</ixy>
                        <ixz>0</ixz>
                        <iyy>0.043333</iyy>
                        <iyz>0</iyz>
                        <izz>0.08</izz>
                    </inertia>
                </inertial>
                <visual name='visual'>
                    <geometry>
                        <cylinder>
                            <radius>0.05</radius>
                            <length>0.04</length>
                        </cylinder>
                    </geometry>
                    <material>
                        <ambient>1.0 0.0 0.0 1</ambient>
                        <diffuse>1.0 0.0 0.0 1</diffuse>
                        <specular>1.0 0.0 0.0 1</specular>
                    </material>
                </visual>
                <collision name='collision'>
                    <geometry>
                        <cylinder>
                            <radius>0.05</radius>
                            <length>0.04</length>
                        </cylinder>
                    </geometry>
                </collision>
            </link>

            <!--Rear left wheel-->
            <link name='rear_left_wheel'>
                <pose relative_to="chassis">-0.2 0.15 -0.05 -1.5707 0 0</pose> <!--angles are in radian-->
                <inertial>
                    <mass>1</mass>
                    <inertia>
                        <ixx>0.043333</ixx>
                        <ixy>0</ixy>
                        <ixz>0</ixz>
                        <iyy>0.043333</iyy>
                        <iyz>0</iyz>
                        <izz>0.08</izz>
                    </inertia>
                </inertial>
                <visual name='visual'>
                    <geometry>
                        <cylinder>
                            <radius>0.05</radius>
                            <length>0.04</length>
                        </cylinder>
                    </geometry>
                    <material>
                        <ambient>1.0 0.0 0.0 1</ambient>
                        <diffuse>1.0 0.0 0.0 1</diffuse>
                        <specular>1.0 0.0 0.0 1</specular>
                    </material>
                </visual>
                <collision name='collision'>
                    <geometry>
                        <cylinder>
                            <radius>0.05</radius>
                            <length>0.04</length>
                        </cylinder>
                    </geometry>
                </collision>
            </link>

            <!--Rear right wheel-->
            <link name='rear_right_wheel'>
                <pose relative_to="chassis">-0.2 -0.15 -0.05 -1.5707 0 0</pose> <!--angles are in radian-->
                <inertial>
                    <mass>1</mass>
                    <inertia>
                        <ixx>0.043333</ixx>
                        <ixy>0</ixy>
                        <ixz>0</ixz>
                        <iyy>0.043333</iyy>
                        <iyz>0</iyz>
                        <izz>0.08</izz>
                    </inertia>
                </inertial>
                <visual name='visual'>
                    <geometry>
                        <cylinder>
                            <radius>0.05</radius>
                            <length>0.04</length>
                        </cylinder>
                    </geometry>
                    <material>
                        <ambient>1.0 0.0 0.0 1</ambient>
                        <diffuse>1.0 0.0 0.0 1</diffuse>
                        <specular>1.0 0.0 0.0 1</specular>
                    </material>
                </visual>
                <collision name='collision'>
                    <geometry>
                        <cylinder>
                            <radius>0.05</radius>
                            <length>0.04</length>
                        </cylinder>
                    </geometry>
                </collision>
            </link>

            <!-- Ackermann Steering (front wheels steering mechanism) -->
            <joint name="steering_left" type="revolute">
                <parent>chassis</parent>
                <child>front_left_wheel</child>
                <pose relative_to='front_left_wheel'/>
                <axis>
                    <xyz expressed_in='__model__'>0 0 1</xyz>
                    <limit>
                        <lower>-0.5</lower>
                        <upper>0.5</upper>
                    </limit>
                </axis>
            </joint>

            <joint name="steering_right" type="revolute">
                <parent>chassis</parent>
                <child>front_right_wheel</child>
                <pose relative_to='front_right_wheel'/>
                <axis>
                    <xyz expressed_in='__model__'>0 0 1</xyz>
                    <limit>
                        <lower>-0.5</lower>
                        <upper>0.5</upper>
                    </limit>
                </axis>
            </joint>

            <!-- Rear Wheel Fixed Joints -->
            <joint name="rear_left_wheel_joint" type="revolute">
                <pose relative_to='rear_left_wheel'/>
                <parent>chassis</parent>
                <child>rear_left_wheel</child>
                <axis>
                    <xyz expressed_in='__model__'>0 1 0</xyz>
                    <limit>
                        <lower>-1.79769e+308</lower>    <!--negative infinity-->
                        <upper>1.79769e+308</upper>     <!--positive infinity-->
                    </limit>
                </axis>
            </joint>

            <joint name="rear_right_wheel_joint" type="revolute">
                <pose relative_to='rear_right_wheel'/>
                <parent>chassis</parent>
                <child>rear_right_wheel</child>
                <axis>
                    <xyz expressed_in='__model__'>0 1 0</xyz>
                    <limit>
                        <lower>-1.79769e+308</lower>    <!--negative infinity-->
                        <upper>1.79769e+308</upper>     <!--positive infinity-->
                    </limit>
                </axis>
            </joint>

            <!-- Plugin DiffDrive para as rodas traseiras -->
            <!--plugin
                filename="libignition-gazebo-diff-drive-system.so"
                name="ignition::gazebo::systems::DiffDrive">
                <left_joint>rear_left_wheel_joint</left_joint>
                <right_joint>rear_right_wheel_joint</right_joint>
                <wheel_separation>1.4</wheel_separation>
                <wheel_radius>0.1</wheel_radius>
                <odom_publish_frequency>1</odom_publish_frequency>
                <topic>cmd_vel</topic>
            </plugin-->

            <!-- Plugin JointController para controlar as rodas dianteiras -->
            <!--plugin
                filename="libignition-gazebo-joint-controller-system.so"
                name="ignition::gazebo::systems::JointController">
                <joint_name>steering_left</joint_name>
                <joint_name>steering_right</joint_name>
                <topic>steering_cmd</topic>
            </plugin-->

            <plugin
                filename="libignition-gazebo-ackermann-drive-system.so"
                name="ignition::gazebo::systems::AckermannDrive">
                
                <!-- Juntas das rodas controladas pela direção (frontal esquerda e direita) -->
                <steering_left_joint>steering_left</steering_left_joint>
                <steering_right_joint>steering_right</steering_right_joint>

                <!-- Juntas das rodas controladas pela tração (traseira esquerda e direita) -->
                <left_joint>rear_left_wheel_joint</left_joint>
                <right_joint>rear_right_wheel_joint</right_joint>

                <!-- Parâmetros do controle -->
                <wheel_separation>1.2</wheel_separation>       <!-- Distância entre as rodas esquerda e direita -->
                <wheel_base>1.5</wheel_base>                   <!-- Distância entre as rodas dianteiras e traseiras -->
                <wheel_radius>0.2</wheel_radius>               <!-- Raio das rodas -->
                <steering_limit>0.5</steering_limit>           <!-- Limite do ângulo de direção em radianos -->
                
                <!-- Tópicos ROS para comandos de controle -->
                <topic>cmd_vel</topic>                         <!-- Tópico para comandos de velocidade (linear e angular) -->
                <steering_topic>steering_cmd</steering_topic>  <!-- Tópico para comandos de direção (ângulo de direção) -->
                <odom_topic>odom</odom_topic>                  <!-- Tópico para odometria -->
                </plugin>
        </model>
    </world>
</sdf>