<?xml version="1.0"?>
<robot name="ackermann_robot" xmlns:xacro="http://www.ros.org/wiki/xacro">

  <xacro:property name="pi" value="3.14"/>
  <xacro:property name="wheel_roll_angle" value="${pi/2}"/>

  <!-- Base Link (Chassis) -->
  <link name="base_link">
    <visual>
      <origin xyz="0 0 0.1" rpy="0 0 0"/>
      <geometry>
        <box size="0.5 0.3 0.1"/>
      </geometry>
    </visual>
    <collision>
      <origin xyz="0 0 0.1" rpy="0 0 0"/>
      <geometry>
        <box size="0.5 0.3 0.1"/>
      </geometry>
    </collision>
    <inertial>
      <origin xyz="0 0 0.1" rpy="0 0 0"/>
      <mass value="5.0"/>
      <inertia ixx="0.083" ixy="0" ixz="0" iyy="0.083" iyz="0" izz="0.083"/>
    </inertial>
  </link>

  <link name="steering_left_wheel">
    <visual>
      <origin xyz="0 0 0" rpy="${wheel_roll_angle} 0 0"/>
      <geometry>
        <cylinder radius="0.1" length="0.08"/>
      </geometry>
    </visual>
    <collision>
      <origin xyz="0 0 0" rpy="${wheel_roll_angle} 0 0"/>
      <geometry>
        <cylinder radius="0.1" length="0.08"/>
      </geometry>
      <friction>
        <ode>
          <mu>10.0</mu>
          <mu2>10.0</mu2>
          <slip1>0.0</slip1>
          <slip2>0.0</slip2>
        </ode>
      </friction>
    </collision>
    <inertial>
      <origin xyz="0 0 0" rpy="${wheel_roll_angle} 0 0"/>
      <mass value="1.0"/>
      <inertia ixx="0.001" ixy="0" ixz="0" iyy="0.001" iyz="0" izz="0.001"/>
    </inertial>
  </link>

  <link name="steering_right_wheel">
    <visual>
      <origin xyz="0 0 0" rpy="${wheel_roll_angle} 0 0"/>
      <geometry>
        <cylinder radius="0.1" length="0.08"/>
      </geometry>
    </visual>
    <collision>
      <origin xyz="0 0 0" rpy="${wheel_roll_angle} 0 0"/>
      <geometry>
        <cylinder radius="0.1" length="0.08"/>
      </geometry>
      <friction>
        <ode>
          <mu>10.0</mu>
          <mu2>10.0</mu2>
          <slip1>0.0</slip1>
          <slip2>0.0</slip2>
        </ode>
      </friction>
    </collision>
    <inertial>
      <origin xyz="0 0 0" rpy="${wheel_roll_angle} 0 0"/>
      <mass value="1.0"/>
      <inertia ixx="0.001" ixy="0" ixz="0" iyy="0.001" iyz="0" izz="0.001"/>
    </inertial>
  </link>
  
  <link name="rear_left_wheel">
    <visual>
      <origin xyz="0 0 0" rpy="${wheel_roll_angle} 0 0"/>
      <geometry>
        <cylinder radius="0.1" length="0.08"/>
      </geometry>
    </visual>
    <collision>
      <origin xyz="0 0 0" rpy="${wheel_roll_angle} 0 0"/>
      <geometry>
        <cylinder radius="0.1" length="0.08"/>
      </geometry>
      <friction>
        <ode>
          <mu>10.0</mu>
          <mu2>10.0</mu2>
          <slip1>0.0</slip1>
          <slip2>0.0</slip2>
        </ode>
      </friction>
    </collision>
    <inertial>
      <origin xyz="0 0 0" rpy="${wheel_roll_angle} 0 0"/>
      <mass value="1.0"/>
      <inertia ixx="0.001" ixy="0" ixz="0" iyy="0.001" iyz="0" izz="0.001"/>
    </inertial>
  </link>

  <link name="rear_right_wheel">
    <visual>
      <origin xyz="0 0 0" rpy="${wheel_roll_angle} 0 0"/>
      <geometry>
        <cylinder radius="0.1" length="0.08"/>
      </geometry>
    </visual>
    <collision>
      <origin xyz="0 0 0" rpy="${wheel_roll_angle} 0 0"/>
      <geometry>
        <cylinder radius="0.1" length="0.08"/>
      </geometry>
      <friction>
        <ode>
          <mu>10.0</mu>
          <mu2>10.0</mu2>
          <slip1>0.0</slip1>
          <slip2>0.0</slip2>
        </ode>
      </friction>
    </collision>
    <inertial>
      <origin xyz="0 0 0" rpy="${wheel_roll_angle} 0 0"/>
      <mass value="1.0"/>
      <inertia ixx="0.001" ixy="0" ixz="0" iyy="0.001" iyz="0" izz="0.001"/>
    </inertial>
  </link>


  <joint name="rear_left_wheel_joint" type="continuous">
    <parent link="base_link"/>
    <child link="rear_left_wheel"/>
    <origin xyz="-0.2 0.2 0.1" rpy="0 0 0"/>
    <axis xyz="0 1 0" rpy="0 0 0"/>
    <limit effort="100" velocity="100"/>
    <joint_properties damping="1.0" friction="1.0"/>
  </joint>

  <joint name="rear_right_wheel_joint" type="continuous">
    <parent link="base_link"/>
    <child link="rear_right_wheel"/>
    <origin xyz="-0.2 -0.2 0.1" rpy="0 0 0"/>
    <axis xyz="0 1 0" rpy="0 0 0"/>
    <limit effort="100" velocity="100"/>
    <joint_properties damping="1.0" friction="1.0"/>
  </joint>


    <!-- Juntas dianteiras (direcionadas) -->
  <joint name="front_left_steering_joint" type="revolute">
    <parent link="base_link"/>
    <child link="front_left_steering_rotation_link"/>
    <origin xyz="0.2 0.2 0.1" rpy="0 0 0"/>
    <axis xyz="0 0 1"/>
    <limit lower="-0.5236" upper="0.5236" effort="10" velocity="1.0"/> <!-- Limite de direção (±30 graus) -->
  </joint>

  <!--Link intermediário para a rotação da roda dianteira esquerda-->
  <link name="front_left_steering_rotation_link">
    <visual>
        <geometry>
            <box size="0.01 0.01 0.01"/>
        </geometry>
    </visual>
    <inertial>
        <mass value="0.01"/>
        <inertia ixx="0.00001" ixy="0.0" ixz="0.0" iyy="0.00001" iyz="0.0" izz="0.00001"/>
    </inertial>
  </link>

  <!-- Junta de rotação para o eixo y (rotação da roda) -->
  <joint name="front_left_wheel_rotation_joint" type="continuous">
      <parent link="front_left_steering_rotation_link"/>
      <child link="steering_left_wheel"/>
      <origin xyz="0 0 0" rpy="0 0 0"/>
      <axis xyz="0 1 0"/>
      <limit lower="0" upper="0" effort="50" velocity="10.0"/>
  </joint>


  <joint name="front_right_steering_joint" type="revolute">
    <parent link="base_link"/>
    <child link="front_right_steering_rotation_link"/>
    <origin xyz="0.2 -0.2 0.1" rpy="0 0 0"/>
    <axis xyz="0 0 1"/>
    <limit lower="-0.5236" upper="0.5236" effort="10" velocity="1.0"/> <!-- Limite de direção (±30 graus) -->
  </joint>

  <!--Link intermediário para a rotação da roda dianteira esquerda-->
  <link name="front_right_steering_rotation_link">
    <visual>
        <geometry>
            <box size="0.01 0.01 0.01"/>
        </geometry>
    </visual>
    <inertial>
        <mass value="0.01"/>
        <inertia ixx="0.00001" ixy="0.0" ixz="0.0" iyy="0.00001" iyz="0.0" izz="0.00001"/>
    </inertial>
  </link>

  <!-- Junta de rotação para o eixo y (rotação da roda) -->
  <joint name="front_right_wheel_rotation_joint" type="continuous">
    <parent link="front_right_steering_rotation_link"/>
    <child link="steering_right_wheel"/>
    <origin xyz="0 0 0" rpy="0 0 0"/>
    <axis xyz="0 1 0"/>
    <limit effort="100" velocity="100"/>
    <joint_properties damping="1.0" friction="1.0"/>
  </joint>


<transmission name="front_left_steering_trans">
  <type>transmission_interface/SimpleTransmission</type>
  <joint name="front_left_steering_joint">
    <hardwareInterface>hardware_interface/EffortJointInterface</hardwareInterface>
  </joint>
  <actuator name="front_left_steering_motor">
    <mechanicalReduction>1</mechanicalReduction>
  </actuator>
</transmission>

<transmission name="front_right_steering_trans">
  <type>transmission_interface/SimpleTransmission</type>
  <joint name="front_right_steering_joint">
    <hardwareInterface>hardware_interface/EffortJointInterface</hardwareInterface>
  </joint>
  <actuator name="front_right_steering_motor">
    <mechanicalReduction>1</mechanicalReduction>
  </actuator>
</transmission>

<transmission name="rear_left_wheel_trans">
  <type>transmission_interface/SimpleTransmission</type>
  <joint name="rear_left_wheel_joint">
    <!--hardwareInterface>hardware_interface/EffortJointInterface</hardwareInterface-->
    <hardwareInterface>hardware_interface/VelocityJointInterface</hardwareInterface>
  </joint>
  <actuator name="rear_left_wheel_motor">
    <mechanicalReduction>1</mechanicalReduction>
  </actuator>
</transmission>

<transmission name="rear_right_wheel_trans">
  <type>transmission_interface/SimpleTransmission</type>
  <joint name="rear_right_wheel_joint">
    <!--hardwareInterface>hardware_interface/EffortJointInterface</hardwareInterface-->
    <hardwareInterface>hardware_interface/VelocityJointInterface</hardwareInterface>
  </joint>
  <actuator name="rear_right_wheel_motor">
    <mechanicalReduction>1</mechanicalReduction>
  </actuator>
</transmission>

  <gazebo>
    <plugin name="gazebo_ros_control" filename="libgazebo_ros_control.so">
      <robotNamespace>/</robotNamespace>
    </plugin>
  </gazebo>

</robot>
