<?xml version="1.0"?>
<robot name="skid_steer" xmlns:xacro="http://www.ros.org/wiki/xacro">

  <xacro:property name="pi" value="3.14"/>

  <xacro:property name="chassis_length" value="0.5"/>
  <xacro:property name="chassis_width" value="0.3"/>
  <xacro:property name="chassis_height" value="0.1"/>

  <xacro:property name="wheel_radius" value="0.1"/>
  <xacro:property name="wheel_width" value="0.08"/>
  <xacro:property name="wheel_roll_angle" value="${pi/2}"/>

  <!--This link it is just to avoid a warning-->
  <link name="dummy_link"/>

  <!-- Base Link (Chassi) -->
  <link name="base_link">
    <visual>
      <origin xyz="0 0 0.1" rpy="0 0 0"/>
      <geometry>
        <box size="${chassis_length} ${chassis_width} ${chassis_height}"/>
      </geometry>
    </visual>

    <collision>
      <origin xyz="0 0 0.1" rpy="0 0 0"/>
      <geometry>
        <box size="${chassis_length} ${chassis_width} ${chassis_height}"/>
      </geometry>
    </collision>

    <inertial>
      <origin xyz="0 0 0.1" rpy="0 0 0"/>
      <mass value="5.0"/>
      <inertia ixx="0.083" ixy="0" ixz="0" iyy="0.083" iyz="0" izz="0.083"/>
    </inertial>
  </link>


  <!--This joint it is just to avoid a warning-->
  <joint name="fixed_joint" type="fixed">
    <parent link="dummy_link"/>
    <child link="base_link"/>
    <origin xyz="0 0 0" rpy="0 0 0"/>
  </joint>


  <link name="front_left_wheel">
    <visual>
      <origin xyz="0 0 0" rpy="${wheel_roll_angle} 0 0"/>
      <geometry>
        <cylinder radius="${wheel_radius}" length="${wheel_width}"/>
      </geometry>
    </visual>

    <collision>
      <origin xyz="0 0 0" rpy="${wheel_roll_angle} 0 0"/>
      <geometry>
        <cylinder radius="${wheel_radius}" length="${wheel_width}"/>
      </geometry>
      <friction>
        <ode>
          <mu>10.0</mu>
          <mu2>10.0</mu2>
          <slip1>0.0</slip1>
          <slip2>0.0</slip2>
        </ode>
      </friction>
    </collision>

    <inertial>
      <origin xyz="0 0 0" rpy="${wheel_roll_angle} 0 0"/>
      <mass value="1.0"/>
      <inertia ixx="0.001" ixy="0" ixz="0" iyy="0.001" iyz="0" izz="0.001"/>
    </inertial>
  </link>


  <link name="front_right_wheel">
    <visual>
      <origin xyz="0 0 0" rpy="${wheel_roll_angle} 0 0"/>
      <geometry>
        <cylinder radius="${wheel_radius}" length="${wheel_width}"/>
      </geometry>
    </visual>

    <collision>
      <origin xyz="0 0 0" rpy="${wheel_roll_angle} 0 0"/>
      <geometry>
        <cylinder radius="${wheel_radius}" length="${wheel_width}"/>
      </geometry>
      <friction>
        <ode>
          <mu>10.0</mu>
          <mu2>10.0</mu2>
          <slip1>0.0</slip1>
          <slip2>0.0</slip2>
        </ode>
      </friction>
    </collision>

    <inertial>
      <origin xyz="0 0 0" rpy="${wheel_roll_angle} 0 0"/>
      <mass value="1.0"/>
      <inertia ixx="0.001" ixy="0" ixz="0" iyy="0.001" iyz="0" izz="0.001"/>
    </inertial>
  </link>


  <link name="rear_left_wheel">
    <visual>
      <origin xyz="0 0 0" rpy="${wheel_roll_angle} 0 0"/>
      <geometry>
        <cylinder radius="${wheel_radius}" length="${wheel_width}"/>
      </geometry>
    </visual>

    <collision>
      <origin xyz="0 0 0" rpy="${wheel_roll_angle} 0 0"/>
      <geometry>
        <cylinder radius="${wheel_radius}" length="${wheel_width}"/>
      </geometry>
      <friction>
        <ode>
          <mu>10.0</mu>
          <mu2>10.0</mu2>
          <slip1>0.0</slip1>
          <slip2>0.0</slip2>
        </ode>
      </friction>
    </collision>

    <inertial>
      <origin xyz="0 0 0" rpy="${wheel_roll_angle} 0 0"/>
      <mass value="1.0"/>
      <inertia ixx="0.001" ixy="0" ixz="0" iyy="0.001" iyz="0" izz="0.001"/>
    </inertial>
  </link>


  <link name="rear_right_wheel">
    <visual>
      <origin xyz="0 0 0" rpy="${wheel_roll_angle} 0 0"/>
      <geometry>
        <cylinder radius="${wheel_radius}" length="${wheel_width}"/>
      </geometry>
    </visual>

    <collision>
      <origin xyz="0 0 0" rpy="${wheel_roll_angle} 0 0"/>
      <geometry>
        <cylinder radius="${wheel_radius}" length="${wheel_width}"/>
      </geometry>
      <friction>
        <ode>
          <mu>10.0</mu>
          <mu2>10.0</mu2>
          <slip1>0.0</slip1>
          <slip2>0.0</slip2>
        </ode>
      </friction>
    </collision>

    <inertial>
      <origin xyz="0 0 0" rpy="${wheel_roll_angle} 0 0"/>
      <mass value="1.0"/>
      <inertia ixx="0.001" ixy="0" ixz="0" iyy="0.001" iyz="0" izz="0.001"/>
    </inertial>
  </link>


  <joint name="front_left_wheel_joint" type="continuous">
    <parent link="base_link"/>
    <child link="front_left_wheel"/>
    <origin xyz="0.2 0.2 0.1" rpy="0 0 0"/>
    <axis xyz="0 1 0" rpy="0 0 0"/>
    <limit effort="100" velocity="100"/>
    <joint_properties damping="1.0" friction="1.0"/>
  </joint>


  <joint name="front_right_wheel_joint" type="continuous">
    <parent link="base_link"/>
    <child link="front_right_wheel"/>
    <origin xyz="0.2 -0.2 0.1" rpy="0 0 0"/>
    <axis xyz="0 1 0" rpy="0 0 0"/>
    <limit effort="100" velocity="100"/>
    <joint_properties damping="1.0" friction="1.0"/>
  </joint>


  <joint name="rear_left_wheel_joint" type="continuous">
    <parent link="base_link"/>
    <child link="rear_left_wheel"/>
    <origin xyz="-0.2 0.2 0.1" rpy="0 0 0"/>
    <axis xyz="0 1 0" rpy="0 0 0"/>
    <limit effort="100" velocity="100"/>
    <joint_properties damping="1.0" friction="1.0"/>
  </joint>


  <joint name="rear_right_wheel_joint" type="continuous">
    <parent link="base_link"/>
    <child link="rear_right_wheel"/>
    <origin xyz="-0.2 -0.2 0.1" rpy="0 0 0"/>
    <axis xyz="0 1 0" rpy="0 0 0"/>
    <limit effort="100" velocity="100"/>
    <joint_properties damping="1.0" friction="1.0"/>
  </joint>

  <!-- IMU Sensor -->
  <link name="imu_link">
      <inertial>
          <origin xyz="0 0 0" />
          <mass value="0.01" />
          <inertia ixx="0.0001" ixy="0" ixz="0" iyy="0.0001" iyz="0" izz="0.0001" />
      </inertial>

      <visual>
          <origin xyz="0 0 0" />
          <geometry>
              <box size="0.01 0.01 0.01" />
          </geometry>
      </visual>
  </link>

  <joint name="imu_joint" type="fixed">
      <parent link="base_link" />
      <child link="imu_link" />
      <origin xyz="0 0 0.16" rpy="0 0 0" />
  </joint>

  <gazebo>
    <plugin name="imu_controller" filename="libhector_gazebo_ros_imu.so">
      <robotNamespace>/</robotNamespace>
      <updateRate>50.0</updateRate>
      <bodyName>base_link</bodyName>
      <topicName>imu/data</topicName>
      <accelDrift>0.005 0.005 0.005</accelDrift>
      <accelGaussianNoise>0.005 0.005 0.005</accelGaussianNoise>
      <rateDrift>0.005 0.005 0.005 </rateDrift>
      <rateGaussianNoise>0.005 0.005 0.005 </rateGaussianNoise>
      <headingDrift>0.005</headingDrift>
      <headingGaussianNoise>0.005</headingGaussianNoise>
    </plugin>
  </gazebo>


  <!--Sensor LiDAR 3D -->
  <link name="lidar_link">
    <inertial>
        <origin xyz="0 0 0" />
        <mass value="0.01" />
        <inertia ixx="0.0001" ixy="0" ixz="0" iyy="0.0001" iyz="0" izz="0.0001" />
    </inertial>

    <visual>
        <origin xyz="0 0 0" />
        <geometry>
            <box size="0.01 0.01 0.01" />
        </geometry>
    </visual>
  </link>

  <joint name="lidar_joint" type="fixed">
      <parent link="base_link" />
      <child link="lidar_link" />
      <origin xyz="0 0 0.31" rpy="0 0 0" />
  </joint>
  
  <gazebo reference="lidar_link">
    <sensor type="ray" name="laser_livox">
      <pose>0 0 0.0 0 0 0</pose>
      <visualize>false</visualize>
      <always_on>True</always_on>
      <update_rate>10</update_rate>
      <!-- This ray plgin is only for visualization. -->
      <plugin name="gazebo_ros_laser_controller" filename="liblivox_laser_simulation.so">
      <ray>
      <scan>
        <horizontal>
          <samples>100</samples>
          <resolution>1</resolution>
          <min_angle>-3.1415926535897931</min_angle>
          <max_angle>3.1415926535897931</max_angle>
        </horizontal>
        <vertical>
          <samples>50</samples>
          <resolution>1</resolution>
          <min_angle>-3.1415926535897931</min_angle>
          <max_angle>3.1415926535897931</max_angle>
        </vertical>
      </scan>
      <range>
        <min>0.1</min>
        <max>40</max>
        <resolution>1</resolution>
      </range>
      <noise>
        <type>gaussian</type>
        <mean>0.0</mean>
        <stddev>0.0</stddev>
      </noise>
      </ray>
        <visualize>True</visualize>
        <samples>20000</samples>
        <downsample>1</downsample>
        <csv_file_name>mid360-real-centr.csv</csv_file_name>
        <publish_pointcloud_type>2</publish_pointcloud_type>
        <ros_topic>/livox/lidar</ros_topic>
        <frameName>base_link</frameName>
      </plugin>
    </sensor>
  </gazebo>


  <!-- GPS Sensor -->
  <link name="gps_link">
    <inertial>
        <origin xyz="0 0 0" />
        <mass value="0.01" />
        <inertia ixx="0.0001" ixy="0" ixz="0" iyy="0.0001" iyz="0" izz="0.0001" />
    </inertial>

    <visual>
        <origin xyz="0 0 0" />
        <geometry>
            <box size="0.01 0.01 0.01" />
        </geometry>
    </visual>
  </link>

  <joint name="gps_joint" type="fixed">
      <parent link="base_link" />
      <child link="gps_link" />
      <origin xyz="0 0 0.17" rpy="0 0 0" />
  </joint>

  <gazebo>
    <plugin name="gps" filename="libhector_gazebo_ros_gps.so">
      <alwaysOn>1</alwaysOn>
      <updateRate>10.0</updateRate>
      <bodyName>dummy_link</bodyName>
      <topicName>fix</topicName>
      <velocityTopicName>fix_velocity</velocityTopicName>
      <drift>5.0 5.0 5.0</drift>
      <gaussianNoise>0.1 0.1 0.1</gaussianNoise>
      <velocityDrift>0 0 0</velocityDrift>
      <velocityGaussianNoise>0.1 0.1 0.1</velocityGaussianNoise>
    </plugin>
   </gazebo>

  <!-- Plugin de controle de drive diferencial (skid-steer) -->
  <gazebo>
    <plugin name="skid_steer_controller" filename="libgazebo_ros_skid_steer_drive.so">
      <updateRate>100.0</updateRate>
      <robotNamespace>/</robotNamespace>
      <leftFrontJoint>front_left_wheel_joint</leftFrontJoint>
      <rightFrontJoint>front_right_wheel_joint</rightFrontJoint>
      <leftRearJoint>rear_left_wheel_joint</leftRearJoint>
      <rightRearJoint>rear_right_wheel_joint</rightRearJoint>
      <wheelSeparation>0.3</wheelSeparation>
      <wheelDiameter>0.2</wheelDiameter>
      <torque>100</torque>
      <broadcastTF>1</broadcastTF>
      <odometryFrame>map</odometryFrame>
      <commandTopic>cmd_vel</commandTopic>
      <odometryTopic>odom</odometryTopic>
      <robotBaseFrame>base_footprint</robotBaseFrame>
      <covariance_x>0.0001</covariance_x>
      <covariance_y>0.0001</covariance_y>
      <covariance_z>0.0001</covariance_z>
      <covariance_yaw>0.0001</covariance_yaw>
    </plugin>
  </gazebo>

  <!-- Ground truth -->
    <gazebo>
        <plugin name="gazebo_ros_p3d" filename="libgazebo_ros_p3d.so">
            <alwaysOn>true</alwaysOn>
            <updateRate>20.0</updateRate>
            <bodyName>base_link</bodyName>
            <topicName>ground_truth</topicName>
            <robotNamespace>/</robotNamespace>
        </plugin>
    </gazebo>

</robot>
